Workbook

Sheet CGPA (2)
G1: COLLEGE OF ENGINEERING DEPARTMENT OF ELECTRICAL ENGINEERING Academic Year: 2024/2025 Level: 100
G2: COURSE CODE | I2: {=TRANSPOSE('REG. COURSES'!A10:A24)} -> GST | J2: PHY | K2: WU | L2: WU-GST | M2: WU-GST | N2: COS | O2: BUA | P2: MTH | Q2: MTH | R2: MTH | S2: MTH | T2: MTH | U2: MTH | V2: MTH | W2: MTH
I3: {=TRANSPOSE('REG. COURSES'!B10:B24)} -> 111 | J3: 101 | K3: 111 | L3: 101 | M3: 111 | N3: 101 | O3: 101 | P3: 101 | Q3: 103 | R3: 104 | S3: 105 | T3: 106 | U3: 107 | V3: 108 | W3: 109
G4: CREDIT UNITS | I4: {=TRANSPOSE('REG. COURSES'!C10:C24)} -> 2 | J4: 2 | K4: 1 | L4: 2 | M4: 1 | N4: 3 | O4: 2 | P4: 2 | Q4: 2 | R4: 1 | S4: 1 | T4: 1 | U4: 1 | V4: 1 | W4: 1 | AA4: 12 | AC4: 12 | AE4: 13 | AG4: 14 | AI4: 15 | AK4: 15
A5: S/N | B5: MATRIC NUMBER | C5: NAMES | AG5: Score | AH5: Grade | AI5: Score | AJ5: Grade | AK5: Score | AL5: Grade | AM5: Total Unit Registered | AN5: Total Unit Passed | AO5: Total Unit Failed | AP5: Total Grade Point | AQ5: Grade Points Average | AR5: Remarks Outstanding Courses (Total Outstanding Units)
A6: 1 | I6: 70 | J6: 80 | K6: 78 | L6: 76 | M6: 74 | N6: 76 | O6: 86 | P6: 97 | Q6: 84 | R6: 74 | S6: 79 | T6: 72 | U6: 71 | V6: 80 | W6: 70 | X6: 60 | Y6: 61 | Z6: 62 | AA6: 63 | AB6: 64 | AC6: 65 | AD6: 66 | AE6: 67 | AF6: 68 | AG6: 53 | AH6: ='REG. COURSES'!AA10 -> 0 | AI6: 98 | AJ6: 54 | AK6: ='REG. COURSES'!AD10 -> 0 | AL6: 99 | AP6: {=SUM(VLOOKUP(I7:W7,GRADEPOINT!$A$2:$B$7,2,0)*$I$4:$W$4)} -> 115 | AQ6: =ROUND(AP6/AM7,2) -> 5
I7: {=_xlfn.IFS(I6>= 70,"A",I6>=60,"B",I6>=50,"C",I6>=45,"D",I6>=40,"E",I6<40,"F")} -> A | J7: {=_xlfn.IFS(J6>= 70,"A",J6>=60,"B",J6>=50,"C",J6>=45,"D",J6>=40,"E",J6<40,"F")} -> A | K7: {=_xlfn.IFS(K6>= 70,"A",K6>=60,"B",K6>=50,"C",K6>=45,"D",K6>=40,"E",K6<40,"F")} -> A | L7: {=_xlfn.IFS(L6>= 70,"A",L6>=60,"B",L6>=50,"C",L6>=45,"D",L6>=40,"E",L6<40,"F")} -> A | M7: {=_xlfn.IFS(M6>= 70,"A",M6>=60,"B",M6>=50,"C",M6>=45,"D",M6>=40,"E",M6<40,"F")} -> A | N7: {=_xlfn.IFS(N6>= 70,"A",N6>=60,"B",N6>=50,"C",N6>=45,"D",N6>=40,"E",N6<40,"F")} -> A | O7: {=_xlfn.IFS(O6>= 70,"A",O6>=60,"B",O6>=50,"C",O6>=45,"D",O6>=40,"E",O6<40,"F")} -> A | P7: {=_xlfn.IFS(P6>= 70,"A",P6>=60,"B",P6>=50,"C",P6>=45,"D",P6>=40,"E",P6<40,"F")} -> A | ... AF7: {=_xlfn.IFS(AF6>= 70,"A",AF6>=60,"B",AF6>=50,"C",AF6>=45,"D",AF6>=40,"E",AF6<40,"F")} -> B | AG7: {=_xlfn.IFS(BA6>= 70,"A",BA6>=60,"B",BA6>=50,"C",BA6>=45,"D",BA6>=40,"E",BA6<40,"F")} -> F | AH7: {=_xlfn.IFS(BB6>= 70,"A",BB6>=60,"B",BB6>=50,"C",BB6>=45,"D",BB6>=40,"E",BB6<40,"F")} -> F | AI7: {=_xlfn.IFS(BC6>= 70,"A",BC6>=60,"B",BC6>=50,"C",BC6>=45,"D",BC6>=40,"E",BC6<40,"F")} -> F | AJ7: {=_xlfn.IFS(BD6>= 70,"A",BD6>=60,"B",BD6>=50,"C",BD6>=45,"D",BD6>=40,"E",BD6<40,"F")} -> F | AK7: 50 | AL7: {=_xlfn.IFS(AK7>= 70,"A",AK7>=60,"B",AK7>=50,"C",AK7>=45,"D",AK7>=40,"E",AK7<40,"F")} -> C | AM7: =SUMIFS($I$4:$W$4,I6:W6,">0") -> 23 | AN7: =(SUMIFS($I$4:$W$4,I6:W6,">0")-SUMIFS($I$4:$W$4,I7:W7,"F")) -> 23 | AO7: =SUMIFS($I$4:$W$4,I7:W7,"F") -> 0
A8: 2 | I8: 60 | J8: 67 | K8: 65 | L8: 64 | M8: 68 | N8: 69 | O8: 64 | P8: 63 | Q8: 62 | R8: 61 | S8: 60 | T8: 67 | U8: 65 | V8: 66 | W8: 67 | X8: 60 | Y8: 61 | Z8: 62 | AA8: 63 | AB8: 64 | AC8: 65 | AD8: 66 | AE8: 67 | AF8: 68 | AG8: 40 | AH8: {=_xlfn.IFS(AG8>= 70,"A",AG8>=60,"B",AG8>=50,"C",AG8>=45,"D",AG8>=40,"E",AG8<40,"F")} -> E | AI8: 40 | AJ8: {=_xlfn.IFS(AI8>= 70,"A",AI8>=60,"B",AI8>=50,"C",AI8>=45,"D",AI8>=40,"E",AI8<40,"F")} -> E | AK8: 40 | AL8: {=_xlfn.IFS(AK8>= 70,"A",AK8>=60,"B",AK8>=50,"C",AK8>=45,"D",AK8>=40,"E",AK8<40,"F")} -> E | AP8: {=SUM(VLOOKUP(I9:W9,GRADEPOINT!$A$2:$B$7,2,0)*$I$4:$W$4)} -> 92 | AQ8: =ROUND(AP8/AM9,2) -> 4
I9: {=_xlfn.IFS(I8>= 70,"A",I8>=60,"B",I8>=50,"C",I8>=45,"D",I8>=40,"E",I8<40,"F")} -> B | J9: {=_xlfn.IFS(J8>= 70,"A",J8>=60,"B",J8>=50,"C",J8>=45,"D",J8>=40,"E",J8<40,"F")} -> B | K9: {=_xlfn.IFS(K8>= 70,"A",K8>=60,"B",K8>=50,"C",K8>=45,"D",K8>=40,"E",K8<40,"F")} -> B | L9: {=_xlfn.IFS(L8>= 70,"A",L8>=60,"B",L8>=50,"C",L8>=45,"D",L8>=40,"E",L8<40,"F")} -> B | M9: {=_xlfn.IFS(M8>= 70,"A",M8>=60,"B",M8>=50,"C",M8>=45,"D",M8>=40,"E",M8<40,"F")} -> B | N9: {=_xlfn.IFS(N8>= 70,"A",N8>=60,"B",N8>=50,"C",N8>=45,"D",N8>=40,"E",N8<40,"F")} -> B | O9: {=_xlfn.IFS(O8>= 70,"A",O8>=60,"B",O8>=50,"C",O8>=45,"D",O8>=40,"E",O8<40,"F")} -> B | P9: {=_xlfn.IFS(P8>= 70,"A",P8>=60,"B",P8>=50,"C",P8>=45,"D",P8>=40,"E",P8<40,"F")} -> B | ... AF9: {=_xlfn.IFS(AF8>= 70,"A",AF8>=60,"B",AF8>=50,"C",AF8>=45,"D",AF8>=40,"E",AF8<40,"F")} -> B | AG9: 35 | AH9: {=_xlfn.IFS(AG9>= 70,"A",AG9>=60,"B",AG9>=50,"C",AG9>=45,"D",AG9>=40,"E",AG9<40,"F")} -> F | AI9: 35 | AJ9: {=_xlfn.IFS(AI9>= 70,"A",AI9>=60,"B",AI9>=50,"C",AI9>=45,"D",AI9>=40,"E",AI9<40,"F")} -> F | AK9: 35 | AL9: {=_xlfn.IFS(AK9>= 70,"A",AK9>=60,"B",AK9>=50,"C",AK9>=45,"D",AK9>=40,"E",AK9<40,"F")} -> F | AM9: =SUMIFS($I$4:$W$4,I8:W8,">0") -> 23 | AN9: =(SUMIFS($I$4:$W$4,I8:W8,">0")-SUMIFS($I$4:$W$4,I9:W9,"F")) -> 23 | AO9: =SUMIFS($I$4:$W$4,I9:W9,"F") -> 0
A10: 3 | I10: 64 | J10: 34 | K10: 56 | L10: 28 | M10: 78 | N10: 65 | O10: 40 | P10: 74 | Q10: 88 | R10: 61 | S10: 30 | T10: 45 | U10: 49 | V10: 80 | W10: 70 | X10: 60 | Y10: 61 | Z10: 62 | AA10: 63 | AB10: 64 | AC10: 65 | AD10: 66 | AE10: 67 | AF10: 68 | AG10: 60 | AH10: {=_xlfn.IFS(AG10>= 70,"A",AG10>=60,"B",AG10>=50,"C",AG10>=45,"D",AG10>=40,"E",AG10<40,"F")} -> B | AI10: 60 | AJ10: {=_xlfn.IFS(AI10>= 70,"A",AI10>=60,"B",AI10>=50,"C",AI10>=45,"D",AI10>=40,"E",AI10<40,"F")} -> B | AK10: 60 | AL10: {=_xlfn.IFS(AK10>= 70,"A",AK10>=60,"B",AK10>=50,"C",AK10>=45,"D",AK10>=40,"E",AK10<40,"F")} -> B | AP10: {=SUM(VLOOKUP(I11:W11,GRADEPOINT!$A$2:$B$7,2,0)*$I$4:$W$4)} -> 68 | AQ10: =ROUND(AP10/AM11,2) -> 2.96
I11: {=_xlfn.IFS(I10>= 70,"A",I10>=60,"B",I10>=50,"C",I10>=45,"D",I10>=40,"E",I10<40,"F")} -> B | J11: {=_xlfn.IFS(J10>= 70,"A",J10>=60,"B",J10>=50,"C",J10>=45,"D",J10>=40,"E",J10<40,"F")} -> F | K11: {=_xlfn.IFS(K10>= 70,"A",K10>=60,"B",K10>=50,"C",K10>=45,"D",K10>=40,"E",K10<40,"F")} -> C | L11: {=_xlfn.IFS(L10>= 70,"A",L10>=60,"B",L10>=50,"C",L10>=45,"D",L10>=40,"E",L10<40,"F")} -> F | M11: {=_xlfn.IFS(M10>= 70,"A",M10>=60,"B",M10>=50,"C",M10>=45,"D",M10>=40,"E",M10<40,"F")} -> A | N11: {=_xlfn.IFS(N10>= 70,"A",N10>=60,"B",N10>=50,"C",N10>=45,"D",N10>=40,"E",N10<40,"F")} -> B | O11: {=_xlfn.IFS(O10>= 70,"A",O10>=60,"B",O10>=50,"C",O10>=45,"D",O10>=40,"E",O10<40,"F")} -> E | P11: {=_xlfn.IFS(P10>= 70,"A",P10>=60,"B",P10>=50,"C",P10>=45,"D",P10>=40,"E",P10<40,"F")} -> A | ... AF11: {=_xlfn.IFS(AF10>= 70,"A",AF10>=60,"B",AF10>=50,"C",AF10>=45,"D",AF10>=40,"E",AF10<40,"F")} -> B | AG11: 57 | AH11: {=_xlfn.IFS(AG11>= 70,"A",AG11>=60,"B",AG11>=50,"C",AG11>=45,"D",AG11>=40,"E",AG11<40,"F")} -> C | AI11: 57 | AJ11: {=_xlfn.IFS(AI11>= 70,"A",AI11>=60,"B",AI11>=50,"C",AI11>=45,"D",AI11>=40,"E",AI11<40,"F")} -> C | AK11: 57 | AL11: {=_xlfn.IFS(AK11>= 70,"A",AK11>=60,"B",AK11>=50,"C",AK11>=45,"D",AK11>=40,"E",AK11<40,"F")} -> C | AM11: =SUMIFS($I$4:$W$4,I10:W10,">0") -> 23 | AN11: =(SUMIFS($I$4:$W$4,I10:W10,">0")-SUMIFS($I$4:$W$4,I11:W11,"F")) -> 18 | AO11: =SUMIFS($I$4:$W$4,I11:W11,"F") -> 5
A12: 4 | I12: 70 | J12: 70 | K12: 70 | L12: 70 | M12: 70 | N12: 80 | O12: 23 | P12: 34 | Q12: 21 | R12: 56 | S12: 25 | T12: 34 | U12: 31 | V12: 97 | W12: 29 | X12: 60 | Y12: 61 | Z12: 62 | AA12: 63 | AB12: 64 | AC12: 65 | AD12: 66 | AE12: 67 | AF12: 68 | AG12: 67 | AH12: {=_xlfn.IFS(AG12>= 70,"A",AG12>=60,"B",AG12>=50,"C",AG12>=45,"D",AG12>=40,"E",AG12<40,"F")} -> B | AI12: 67 | AJ12: {=_xlfn.IFS(AI12>= 70,"A",AI12>=60,"B",AI12>=50,"C",AI12>=45,"D",AI12>=40,"E",AI12<40,"F")} -> B | AK12: 67 | AL12: {=_xlfn.IFS(AK12>= 70,"A",AK12>=60,"B",AK12>=50,"C",AK12>=45,"D",AK12>=40,"E",AK12<40,"F")} -> B | AP12: {=SUM(VLOOKUP(I13:W13,GRADEPOINT!$A$2:$B$7,2,0)*$I$4:$W$4)} -> 63 | AQ12: =ROUND(AP12/AM13,2) -> 2.74
I13: {=_xlfn.IFS(I12>= 70,"A",I12>=60,"B",I12>=50,"C",I12>=45,"D",I12>=40,"E",I12<40,"F")} -> A | J13: {=_xlfn.IFS(J12>= 70,"A",J12>=60,"B",J12>=50,"C",J12>=45,"D",J12>=40,"E",J12<40,"F")} -> A | K13: {=_xlfn.IFS(K12>= 70,"A",K12>=60,"B",K12>=50,"C",K12>=45,"D",K12>=40,"E",K12<40,"F")} -> A | L13: {=_xlfn.IFS(L12>= 70,"A",L12>=60,"B",L12>=50,"C",L12>=45,"D",L12>=40,"E",L12<40,"F")} -> A | M13: {=_xlfn.IFS(M12>= 70,"A",M12>=60,"B",M12>=50,"C",M12>=45,"D",M12>=40,"E",M12<40,"F")} -> A | N13: {=_xlfn.IFS(N12>= 70,"A",N12>=60,"B",N12>=50,"C",N12>=45,"D",N12>=40,"E",N12<40,"F")} -> A | O13: {=_xlfn.IFS(O12>= 70,"A",O12>=60,"B",O12>=50,"C",O12>=45,"D",O12>=40,"E",O12<40,"F")} -> F | P13: {=_xlfn.IFS(P12>= 70,"A",P12>=60,"B",P12>=50,"C",P12>=45,"D",P12>=40,"E",P12<40,"F")} -> F | ... AF13: {=_xlfn.IFS(AF12>= 70,"A",AF12>=60,"B",AF12>=50,"C",AF12>=45,"D",AF12>=40,"E",AF12<40,"F")} -> B | AG13: 99 | AH13: {=_xlfn.IFS(AG13>= 70,"A",AG13>=60,"B",AG13>=50,"C",AG13>=45,"D",AG13>=40,"E",AG13<40,"F")} -> A | AI13: 99 | AJ13: {=_xlfn.IFS(AI13>= 70,"A",AI13>=60,"B",AI13>=50,"C",AI13>=45,"D",AI13>=40,"E",AI13<40,"F")} -> A | AK13: 99 | AL13: {=_xlfn.IFS(AK13>= 70,"A",AK13>=60,"B",AK13>=50,"C",AK13>=45,"D",AK13>=40,"E",AK13<40,"F")} -> A | AM13: =SUMIFS($I$4:$W$4,I12:W12,">0") -> 23 | AN13: =(SUMIFS($I$4:$W$4,I12:W12,">0")-SUMIFS($I$4:$W$4,I13:W13,"F")) -> 13 | AO13: =SUMIFS($I$4:$W$4,I13:W13,"F") -> 10
A14: 5 | I14: 45 | J14: 46 | K14: 47 | L14: 48 | M14: 49 | N14: 50 | O14: 51 | P14: 52 | Q14: 53 | R14: 54 | S14: 55 | T14: 56 | U14: 57 | V14: 58 | W14: 59 | X14: 60 | Y14: 61 | Z14: 62 | AA14: 63 | AB14: 64 | AC14: 65 | AD14: 66 | AE14: 67 | AF14: 68 | AG14: 46 | AH14: {=_xlfn.IFS(AG14>= 70,"A",AG14>=60,"B",AG14>=50,"C",AG14>=45,"D",AG14>=40,"E",AG14<40,"F")} -> D | AI14: 46 | AJ14: {=_xlfn.IFS(AI14>= 70,"A",AI14>=60,"B",AI14>=50,"C",AI14>=45,"D",AI14>=40,"E",AI14<40,"F")} -> D | AK14: 46 | AL14: {=_xlfn.IFS(AK14>= 70,"A",AK14>=60,"B",AK14>=50,"C",AK14>=45,"D",AK14>=40,"E",AK14<40,"F")} -> D | AP14: {=SUM(VLOOKUP(I15:W15,GRADEPOINT!$A$2:$B$7,2,0)*$I$4:$W$4)} -> 61 | AQ14: =ROUND(AP14/AM15,2) -> 2.65
I15: {=_xlfn.IFS(I14>= 70,"A",I14>=60,"B",I14>=50,"C",I14>=45,"D",I14>=40,"E",I14<40,"F")} -> D | J15: {=_xlfn.IFS(J14>= 70,"A",J14>=60,"B",J14>=50,"C",J14>=45,"D",J14>=40,"E",J14<40,"F")} -> D | K15: {=_xlfn.IFS(K14>= 70,"A",K14>=60,"B",K14>=50,"C",K14>=45,"D",K14>=40,"E",K14<40,"F")} -> D | L15: {=_xlfn.IFS(L14>= 70,"A",L14>=60,"B",L14>=50,"C",L14>=45,"D",L14>=40,"E",L14<40,"F")} -> D | M15: {=_xlfn.IFS(M14>= 70,"A",M14>=60,"B",M14>=50,"C",M14>=45,"D",M14>=40,"E",M14<40,"F")} -> D | N15: {=_xlfn.IFS(N14>= 70,"A",N14>=60,"B",N14>=50,"C",N14>=45,"D",N14>=40,"E",N14<40,"F")} -> C | O15: {=_xlfn.IFS(O14>= 70,"A",O14>=60,"B",O14>=50,"C",O14>=45,"D",O14>=40,"E",O14<40,"F")} -> C | P15: {=_xlfn.IFS(P14>= 70,"A",P14>=60,"B",P14>=50,"C",P14>=45,"D",P14>=40,"E",P14<40,"F")} -> C | ... AF15: {=_xlfn.IFS(AF14>= 70,"A",AF14>=60,"B",AF14>=50,"C",AF14>=45,"D",AF14>=40,"E",AF14<40,"F")} -> B | AG15: 5 | AH15: {=_xlfn.IFS(AG15>= 70,"A",AG15>=60,"B",AG15>=50,"C",AG15>=45,"D",AG15>=40,"E",AG15<40,"F")} -> F | AI15: 5 | AJ15: {=_xlfn.IFS(AI15>= 70,"A",AI15>=60,"B",AI15>=50,"C",AI15>=45,"D",AI15>=40,"E",AI15<40,"F")} -> F | AK15: 5 | AL15: {=_xlfn.IFS(AK15>= 70,"A",AK15>=60,"B",AK15>=50,"C",AK15>=45,"D",AK15>=40,"E",AK15<40,"F")} -> F | AM15: =SUMIFS($I$4:$W$4,I14:W14,">0") -> 23 | AN15: =(SUMIFS($I$4:$W$4,I14:W14,">0")-SUMIFS($I$4:$W$4,I15:W15,"F")) -> 23 | AO15: =SUMIFS($I$4:$W$4,I15:W15,"F") -> 0
A16: 6 | I16: 45 | J16: 46 | K16: 47 | L16: 48 | M16: 49 | N16: 50 | O16: 51 | P16: 52 | Q16: 53 | R16: 54 | S16: 55 | T16: 56 | U16: 57 | V16: 58 | W16: 59 | X16: 60 | Y16: 61 | Z16: 62 | AA16: 63 | AB16: 64 | AC16: 65 | AD16: 66 | AE16: 67 | AF16: 68 | AG16: 98 | AH16: {=_xlfn.IFS(AG16>= 70,"A",AG16>=60,"B",AG16>=50,"C",AG16>=45,"D",AG16>=40,"E",AG16<40,"F")} -> A | AI16: 76 | AJ16: {=_xlfn.IFS(AI16>= 70,"A",AI16>=60,"B",AI16>=50,"C",AI16>=45,"D",AI16>=40,"E",AI16<40,"F")} -> A | AK16: 76 | AL16: {=_xlfn.IFS(AK16>= 70,"A",AK16>=60,"B",AK16>=50,"C",AK16>=45,"D",AK16>=40,"E",AK16<40,"F")} -> A | AP16: {=SUM(VLOOKUP(I17:W17,GRADEPOINT!$A$2:$B$7,2,0)*$I$4:$W$4)} -> 61 | AQ16: =ROUND(AP16/AM17,2) -> 2.65
I17: {=_xlfn.IFS(I16>= 70,"A",I16>=60,"B",I16>=50,"C",I16>=45,"D",I16>=40,"E",I16<40,"F")} -> D | J17: {=_xlfn.IFS(J16>= 70,"A",J16>=60,"B",J16>=50,"C",J16>=45,"D",J16>=40,"E",J16<40,"F")} -> D | K17: {=_xlfn.IFS(K16>= 70,"A",K16>=60,"B",K16>=50,"C",K16>=45,"D",K16>=40,"E",K16<40,"F")} -> D | L17: {=_xlfn.IFS(L16>= 70,"A",L16>=60,"B",L16>=50,"C",L16>=45,"D",L16>=40,"E",L16<40,"F")} -> D | M17: {=_xlfn.IFS(M16>= 70,"A",M16>=60,"B",M16>=50,"C",M16>=45,"D",M16>=40,"E",M16<40,"F")} -> D | N17: {=_xlfn.IFS(N16>= 70,"A",N16>=60,"B",N16>=50,"C",N16>=45,"D",N16>=40,"E",N16<40,"F")} -> C | O17: {=_xlfn.IFS(O16>= 70,"A",O16>=60,"B",O16>=50,"C",O16>=45,"D",O16>=40,"E",O16<40,"F")} -> C | P17: {=_xlfn.IFS(P16>= 70,"A",P16>=60,"B",P16>=50,"C",P16>=45,"D",P16>=40,"E",P16<40,"F")} -> C | ... AF17: {=_xlfn.IFS(AF16>= 70,"A",AF16>=60,"B",AF16>=50,"C",AF16>=45,"D",AF16>=40,"E",AF16<40,"F")} -> B | AH17: {=_xlfn.IFS(AG17>= 70,"A",AG17>=60,"B",AG17>=50,"C",AG17>=45,"D",AG17>=40,"E",AG17<40,"F")} -> F | AJ17: {=_xlfn.IFS(AI17>= 70,"A",AI17>=60,"B",AI17>=50,"C",AI17>=45,"D",AI17>=40,"E",AI17<40,"F")} -> F | AL17: {=_xlfn.IFS(AK17>= 70,"A",AK17>=60,"B",AK17>=50,"C",AK17>=45,"D",AK17>=40,"E",AK17<40,"F")} -> F | AM17: =SUMIFS($I$4:$W$4,I16:W16,">0") -> 23 | AN17: =(SUMIFS($I$4:$W$4,I16:W16,">0")-SUMIFS($I$4:$W$4,I17:W17,"F")) -> 23 | AO17: =SUMIFS($I$4:$W$4,I17:W17,"F") -> 0
A18: 7 | I18: 45 | J18: 46 | K18: 47 | L18: 48 | M18: 49 | N18: 50 | O18: 51 | P18: 52 | Q18: 53 | R18: 54 | S18: 55 | T18: 56 | U18: 57 | V18: 58 | W18: 59 | X18: 60 | Y18: 61 | Z18: 62 | AA18: 63 | AB18: 64 | AC18: 65 | AD18: 66 | AE18: 67 | AF18: 68 | AH18: {=_xlfn.IFS(AG18>= 70,"A",AG18>=60,"B",AG18>=50,"C",AG18>=45,"D",AG18>=40,"E",AG18<40,"F")} -> F | AJ18: {=_xlfn.IFS(AI18>= 70,"A",AI18>=60,"B",AI18>=50,"C",AI18>=45,"D",AI18>=40,"E",AI18<40,"F")} -> F | AL18: {=_xlfn.IFS(AK18>= 70,"A",AK18>=60,"B",AK18>=50,"C",AK18>=45,"D",AK18>=40,"E",AK18<40,"F")} -> F | AP18: {=SUM(VLOOKUP(I19:W19,GRADEPOINT!$A$2:$B$7,2,0)*$I$4:$W$4)} -> 61 | AQ18: =ROUND(AP18/AM19,2) -> 2.65
I19: {=_xlfn.IFS(I18>= 70,"A",I18>=60,"B",I18>=50,"C",I18>=45,"D",I18>=40,"E",I18<40,"F")} -> D | J19: {=_xlfn.IFS(J18>= 70,"A",J18>=60,"B",J18>=50,"C",J18>=45,"D",J18>=40,"E",J18<40,"F")} -> D | K19: {=_xlfn.IFS(K18>= 70,"A",K18>=60,"B",K18>=50,"C",K18>=45,"D",K18>=40,"E",K18<40,"F")} -> D | L19: {=_xlfn.IFS(L18>= 70,"A",L18>=60,"B",L18>=50,"C",L18>=45,"D",L18>=40,"E",L18<40,"F")} -> D | M19: {=_xlfn.IFS(M18>= 70,"A",M18>=60,"B",M18>=50,"C",M18>=45,"D",M18>=40,"E",M18<40,"F")} -> D | N19: {=_xlfn.IFS(N18>= 70,"A",N18>=60,"B",N18>=50,"C",N18>=45,"D",N18>=40,"E",N18<40,"F")} -> C | O19: {=_xlfn.IFS(O18>= 70,"A",O18>=60,"B",O18>=50,"C",O18>=45,"D",O18>=40,"E",O18<40,"F")} -> C | P19: {=_xlfn.IFS(P18>= 70,"A",P18>=60,"B",P18>=50,"C",P18>=45,"D",P18>=40,"E",P18<40,"F")} -> C | ... AF19: {=_xlfn.IFS(AF18>= 70,"A",AF18>=60,"B",AF18>=50,"C",AF18>=45,"D",AF18>=40,"E",AF18<40,"F")} -> B | AH19: {=_xlfn.IFS(AG19>= 70,"A",AG19>=60,"B",AG19>=50,"C",AG19>=45,"D",AG19>=40,"E",AG19<40,"F")} -> F | AJ19: {=_xlfn.IFS(AI19>= 70,"A",AI19>=60,"B",AI19>=50,"C",AI19>=45,"D",AI19>=40,"E",AI19<40,"F")} -> F | AL19: {=_xlfn.IFS(AK19>= 70,"A",AK19>=60,"B",AK19>=50,"C",AK19>=45,"D",AK19>=40,"E",AK19<40,"F")} -> F | AM19: =SUMIFS($I$4:$W$4,I18:W18,">0") -> 23 | AN19: =(SUMIFS($I$4:$W$4,I18:W18,">0")-SUMIFS($I$4:$W$4,I19:W19,"F")) -> 23 | AO19: =SUMIFS($I$4:$W$4,I19:W19,"F") -> 0
A20: 8 | I20: 45 | J20: 46 | K20: 47 | L20: 48 | M20: 49 | N20: 50 | O20: 51 | P20: 52 | Q20: 53 | R20: 54 | S20: 55 | T20: 56 | U20: 57 | V20: 58 | W20: 59 | X20: 60 | Y20: 61 | Z20: 62 | AA20: 63 | AB20: 64 | AC20: 65 | AD20: 66 | AE20: 67 | AF20: 68 | AH20: {=_xlfn.IFS(AG20>= 70,"A",AG20>=60,"B",AG20>=50,"C",AG20>=45,"D",AG20>=40,"E",AG20<40,"F")} -> F | AJ20: {=_xlfn.IFS(AI20>= 70,"A",AI20>=60,"B",AI20>=50,"C",AI20>=45,"D",AI20>=40,"E",AI20<40,"F")} -> F | AL20: {=_xlfn.IFS(AK20>= 70,"A",AK20>=60,"B",AK20>=50,"C",AK20>=45,"D",AK20>=40,"E",AK20<40,"F")} -> F | AP20: {=SUM(VLOOKUP(I21:W21,GRADEPOINT!$A$2:$B$7,2,0)*$I$4:$W$4)} -> 61 | AQ20: =ROUND(AP20/AM21,2) -> 2.65
I21: {=_xlfn.IFS(I20>= 70,"A",I20>=60,"B",I20>=50,"C",I20>=45,"D",I20>=40,"E",I20<40,"F")} -> D | J21: {=_xlfn.IFS(J20>= 70,"A",J20>=60,"B",J20>=50,"C",J20>=45,"D",J20>=40,"E",J20<40,"F")} -> D | K21: {=_xlfn.IFS(K20>= 70,"A",K20>=60,"B",K20>=50,"C",K20>=45,"D",K20>=40,"E",K20<40,"F")} -> D | L21: {=_xlfn.IFS(L20>= 70,"A",L20>=60,"B",L20>=50,"C",L20>=45,"D",L20>=40,"E",L20<40,"F")} -> D | M21: {=_xlfn.IFS(M20>= 70,"A",M20>=60,"B",M20>=50,"C",M20>=45,"D",M20>=40,"E",M20<40,"F")} -> D | N21: {=_xlfn.IFS(N20>= 70,"A",N20>=60,"B",N20>=50,"C",N20>=45,"D",N20>=40,"E",N20<40,"F")} -> C | O21: {=_xlfn.IFS(O20>= 70,"A",O20>=60,"B",O20>=50,"C",O20>=45,"D",O20>=40,"E",O20<40,"F")} -> C | P21: {=_xlfn.IFS(P20>= 70,"A",P20>=60,"B",P20>=50,"C",P20>=45,"D",P20>=40,"E",P20<40,"F")} -> C | ... AF21: {=_xlfn.IFS(AF20>= 70,"A",AF20>=60,"B",AF20>=50,"C",AF20>=45,"D",AF20>=40,"E",AF20<40,"F")} -> B | AH21: {=_xlfn.IFS(AG21>= 70,"A",AG21>=60,"B",AG21>=50,"C",AG21>=45,"D",AG21>=40,"E",AG21<40,"F")} -> F | AJ21: {=_xlfn.IFS(AI21>= 70,"A",AI21>=60,"B",AI21>=50,"C",AI21>=45,"D",AI21>=40,"E",AI21<40,"F")} -> F | AL21: {=_xlfn.IFS(AK21>= 70,"A",AK21>=60,"B",AK21>=50,"C",AK21>=45,"D",AK21>=40,"E",AK21<40,"F")} -> F | AM21: =SUMIFS($I$4:$W$4,I20:W20,">0") -> 23 | AN21: =(SUMIFS($I$4:$W$4,I20:W20,">0")-SUMIFS($I$4:$W$4,I21:W21,"F")) -> 23 | AO21: =SUMIFS($I$4:$W$4,I21:W21,"F") -> 0
A22: 9 | I22: 45 | J22: 46 | K22: 47 | L22: 48 | M22: 49 | N22: 50 | O22: 51 | P22: 52 | Q22: 53 | R22: 54 | S22: 55 | T22: 56 | U22: 57 | V22: 58 | W22: 59 | X22: 60 | Y22: 61 | Z22: 62 | AA22: 63 | AB22: 64 | AC22: 65 | AD22: 66 | AE22: 67 | AF22: 68 | AH22: {=_xlfn.IFS(AG22>= 70,"A",AG22>=60,"B",AG22>=50,"C",AG22>=45,"D",AG22>=40,"E",AG22<40,"F")} -> F | AJ22: {=_xlfn.IFS(AI22>= 70,"A",AI22>=60,"B",AI22>=50,"C",AI22>=45,"D",AI22>=40,"E",AI22<40,"F")} -> F | AL22: {=_xlfn.IFS(AK22>= 70,"A",AK22>=60,"B",AK22>=50,"C",AK22>=45,"D",AK22>=40,"E",AK22<40,"F")} -> F | AP22: {=SUM(VLOOKUP(I23:W23,GRADEPOINT!$A$2:$B$7,2,0)*$I$4:$W$4)} -> 61 | AQ22: =ROUND(AP22/AM23,2) -> 2.65
I23: {=_xlfn.IFS(I22>= 70,"A",I22>=60,"B",I22>=50,"C",I22>=45,"D",I22>=40,"E",I22<40,"F")} -> D | J23: {=_xlfn.IFS(J22>= 70,"A",J22>=60,"B",J22>=50,"C",J22>=45,"D",J22>=40,"E",J22<40,"F")} -> D | K23: {=_xlfn.IFS(K22>= 70,"A",K22>=60,"B",K22>=50,"C",K22>=45,"D",K22>=40,"E",K22<40,"F")} -> D | L23: {=_xlfn.IFS(L22>= 70,"A",L22>=60,"B",L22>=50,"C",L22>=45,"D",L22>=40,"E",L22<40,"F")} -> D | M23: {=_xlfn.IFS(M22>= 70,"A",M22>=60,"B",M22>=50,"C",M22>=45,"D",M22>=40,"E",M22<40,"F")} -> D | N23: {=_xlfn.IFS(N22>= 70,"A",N22>=60,"B",N22>=50,"C",N22>=45,"D",N22>=40,"E",N22<40,"F")} -> C | O23: {=_xlfn.IFS(O22>= 70,"A",O22>=60,"B",O22>=50,"C",O22>=45,"D",O22>=40,"E",O22<40,"F")} -> C | P23: {=_xlfn.IFS(P22>= 70,"A",P22>=60,"B",P22>=50,"C",P22>=45,"D",P22>=40,"E",P22<40,"F")} -> C | ... AF23: {=_xlfn.IFS(AF22>= 70,"A",AF22>=60,"B",AF22>=50,"C",AF22>=45,"D",AF22>=40,"E",AF22<40,"F")} -> B | AH23: {=_xlfn.IFS(AG23>= 70,"A",AG23>=60,"B",AG23>=50,"C",AG23>=45,"D",AG23>=40,"E",AG23<40,"F")} -> F | AJ23: {=_xlfn.IFS(AI23>= 70,"A",AI23>=60,"B",AI23>=50,"C",AI23>=45,"D",AI23>=40,"E",AI23<40,"F")} -> F | AL23: {=_xlfn.IFS(AK23>= 70,"A",AK23>=60,"B",AK23>=50,"C",AK23>=45,"D",AK23>=40,"E",AK23<40,"F")} -> F | AM23: =SUMIFS($I$4:$W$4,I22:W22,">0") -> 23 | AN23: =(SUMIFS($I$4:$W$4,I22:W22,">0")-SUMIFS($I$4:$W$4,I23:W23,"F")) -> 23 | AO23: =SUMIFS($I$4:$W$4,I23:W23,"F") -> 0
A24: 10 | I24: 45 | J24: 46 | K24: 47 | L24: 48 | M24: 49 | N24: 50 | O24: 51 | P24: 52 | Q24: 53 | R24: 54 | S24: 55 | T24: 56 | U24: 57 | V24: 58 | W24: 59 | X24: 60 | Y24: 61 | Z24: 62 | AA24: 63 | AB24: 64 | AC24: 65 | AD24: 66 | AE24: 67 | AF24: 68 | AH24: {=_xlfn.IFS(AG24>= 70,"A",AG24>=60,"B",AG24>=50,"C",AG24>=45,"D",AG24>=40,"E",AG24<40,"F")} -> F | AJ24: {=_xlfn.IFS(AI24>= 70,"A",AI24>=60,"B",AI24>=50,"C",AI24>=45,"D",AI24>=40,"E",AI24<40,"F")} -> F | AL24: {=_xlfn.IFS(AK24>= 70,"A",AK24>=60,"B",AK24>=50,"C",AK24>=45,"D",AK24>=40,"E",AK24<40,"F")} -> F | AP24: {=SUM(VLOOKUP(I25:W25,GRADEPOINT!$A$2:$B$7,2,0)*$I$4:$W$4)} -> 61 | AQ24: =ROUND(AP24/AM25,2) -> 2.65
I25: {=_xlfn.IFS(I24>= 70,"A",I24>=60,"B",I24>=50,"C",I24>=45,"D",I24>=40,"E",I24<40,"F")} -> D | J25: {=_xlfn.IFS(J24>= 70,"A",J24>=60,"B",J24>=50,"C",J24>=45,"D",J24>=40,"E",J24<40,"F")} -> D | K25: {=_xlfn.IFS(K24>= 70,"A",K24>=60,"B",K24>=50,"C",K24>=45,"D",K24>=40,"E",K24<40,"F")} -> D | L25: {=_xlfn.IFS(L24>= 70,"A",L24>=60,"B",L24>=50,"C",L24>=45,"D",L24>=40,"E",L24<40,"F")} -> D | M25: {=_xlfn.IFS(M24>= 70,"A",M24>=60,"B",M24>=50,"C",M24>=45,"D",M24>=40,"E",M24<40,"F")} -> D | N25: {=_xlfn.IFS(N24>= 70,"A",N24>=60,"B",N24>=50,"C",N24>=45,"D",N24>=40,"E",N24<40,"F")} -> C | O25: {=_xlfn.IFS(O24>= 70,"A",O24>=60,"B",O24>=50,"C",O24>=45,"D",O24>=40,"E",O24<40,"F")} -> C | P25: {=_xlfn.IFS(P24>= 70,"A",P24>=60,"B",P24>=50,"C",P24>=45,"D",P24>=40,"E",P24<40,"F")} -> C | ... AF25: {=_xlfn.IFS(AF24>= 70,"A",AF24>=60,"B",AF24>=50,"C",AF24>=45,"D",AF24>=40,"E",AF24<40,"F")} -> B | AH25: {=_xlfn.IFS(AG25>= 70,"A",AG25>=60,"B",AG25>=50,"C",AG25>=45,"D",AG25>=40,"E",AG25<40,"F")} -> F | AJ25: {=_xlfn.IFS(AI25>= 70,"A",AI25>=60,"B",AI25>=50,"C",AI25>=45,"D",AI25>=40,"E",AI25<40,"F")} -> F | AL25: {=_xlfn.IFS(AK25>= 70,"A",AK25>=60,"B",AK25>=50,"C",AK25>=45,"D",AK25>=40,"E",AK25<40,"F")} -> F | AM25: =SUMIFS($I$4:$W$4,I24:W24,">0") -> 23 | AN25: =(SUMIFS($I$4:$W$4,I24:W24,">0")-SUMIFS($I$4:$W$4,I25:W25,"F")) -> 23 | AO25: =SUMIFS($I$4:$W$4,I25:W25,"F") -> 0
A26: 11 | I26: 45 | J26: 46 | K26: 47 | L26: 48 | M26: 49 | N26: 50 | O26: 51 | P26: 52 | Q26: 53 | R26: 54 | S26: 55 | T26: 56 | U26: 57 | V26: 58 | W26: 59 | X26: 60 | Y26: 61 | Z26: 62 | AA26: 63 | AB26: 64 | AC26: 65 | AD26: 66 | AE26: 67 | AF26: 68 | AH26: {=_xlfn.IFS(AG26>= 70,"A",AG26>=60,"B",AG26>=50,"C",AG26>=45,"D",AG26>=40,"E",AG26<40,"F")} -> F | AJ26: {=_xlfn.IFS(AI26>= 70,"A",AI26>=60,"B",AI26>=50,"C",AI26>=45,"D",AI26>=40,"E",AI26<40,"F")} -> F | AL26: {=_xlfn.IFS(AK26>= 70,"A",AK26>=60,"B",AK26>=50,"C",AK26>=45,"D",AK26>=40,"E",AK26<40,"F")} -> F | AP26: {=SUM(VLOOKUP(I27:W27,GRADEPOINT!$A$2:$B$7,2,0)*$I$4:$W$4)} -> 61 | AQ26: =ROUND(AP26/AM27,2) -> 2.65
I27: {=_xlfn.IFS(I26>= 70,"A",I26>=60,"B",I26>=50,"C",I26>=45,"D",I26>=40,"E",I26<40,"F")} -> D | J27: {=_xlfn.IFS(J26>= 70,"A",J26>=60,"B",J26>=50,"C",J26>=45,"D",J26>=40,"E",J26<40,"F")} -> D | K27: {=_xlfn.IFS(K26>= 70,"A",K26>=60,"B",K26>=50,"C",K26>=45,"D",K26>=40,"E",K26<40,"F")} -> D | L27: {=_xlfn.IFS(L26>= 70,"A",L26>=60,"B",L26>=50,"C",L26>=45,"D",L26>=40,"E",L26<40,"F")} -> D | M27: {=_xlfn.IFS(M26>= 70,"A",M26>=60,"B",M26>=50,"C",M26>=45,"D",M26>=40,"E",M26<40,"F")} -> D | N27: {=_xlfn.IFS(N26>= 70,"A",N26>=60,"B",N26>=50,"C",N26>=45,"D",N26>=40,"E",N26<40,"F")} -> C | O27: {=_xlfn.IFS(O26>= 70,"A",O26>=60,"B",O26>=50,"C",O26>=45,"D",O26>=40,"E",O26<40,"F")} -> C | P27: {=_xlfn.IFS(P26>= 70,"A",P26>=60,"B",P26>=50,"C",P26>=45,"D",P26>=40,"E",P26<40,"F")} -> C | ... AF27: {=_xlfn.IFS(AF26>= 70,"A",AF26>=60,"B",AF26>=50,"C",AF26>=45,"D",AF26>=40,"E",AF26<40,"F")} -> B | AH27: {=_xlfn.IFS(AG27>= 70,"A",AG27>=60,"B",AG27>=50,"C",AG27>=45,"D",AG27>=40,"E",AG27<40,"F")} -> F | AJ27: {=_xlfn.IFS(AI27>= 70,"A",AI27>=60,"B",AI27>=50,"C",AI27>=45,"D",AI27>=40,"E",AI27<40,"F")} -> F | AL27: {=_xlfn.IFS(AK27>= 70,"A",AK27>=60,"B",AK27>=50,"C",AK27>=45,"D",AK27>=40,"E",AK27<40,"F")} -> F | AM27: =SUMIFS($I$4:$W$4,I26:W26,">0") -> 23 | AN27: =(SUMIFS($I$4:$W$4,I26:W26,">0")-SUMIFS($I$4:$W$4,I27:W27,"F")) -> 23 | AO27: =SUMIFS($I$4:$W$4,I27:W27,"F") -> 0
A28: 12 | I28: 45 | J28: 46 | K28: 47 | L28: 48 | M28: 49 | N28: 50 | O28: 51 | P28: 52 | Q28: 53 | R28: 54 | S28: 55 | T28: 56 | U28: 57 | V28: 58 | W28: 59 | X28: 60 | Y28: 61 | Z28: 62 | AA28: 63 | AB28: 64 | AC28: 65 | AD28: 66 | AE28: 67 | AF28: 68 | AH28: {=_xlfn.IFS(AG28>= 70,"A",AG28>=60,"B",AG28>=50,"C",AG28>=45,"D",AG28>=40,"E",AG28<40,"F")} -> F | AJ28: {=_xlfn.IFS(AI28>= 70,"A",AI28>=60,"B",AI28>=50,"C",AI28>=45,"D",AI28>=40,"E",AI28<40,"F")} -> F | AL28: {=_xlfn.IFS(AK28>= 70,"A",AK28>=60,"B",AK28>=50,"C",AK28>=45,"D",AK28>=40,"E",AK28<40,"F")} -> F | AP28: {=SUM(VLOOKUP(I29:W29,GRADEPOINT!$A$2:$B$7,2,0)*$I$4:$W$4)} -> 61 | AQ28: =ROUND(AP28/AM29,2) -> 2.65
I29: {=_xlfn.IFS(I28>= 70,"A",I28>=60,"B",I28>=50,"C",I28>=45,"D",I28>=40,"E",I28<40,"F")} -> D | J29: {=_xlfn.IFS(J28>= 70,"A",J28>=60,"B",J28>=50,"C",J28>=45,"D",J28>=40,"E",J28<40,"F")} -> D | K29: {=_xlfn.IFS(K28>= 70,"A",K28>=60,"B",K28>=50,"C",K28>=45,"D",K28>=40,"E",K28<40,"F")} -> D | L29: {=_xlfn.IFS(L28>= 70,"A",L28>=60,"B",L28>=50,"C",L28>=45,"D",L28>=40,"E",L28<40,"F")} -> D | M29: {=_xlfn.IFS(M28>= 70,"A",M28>=60,"B",M28>=50,"C",M28>=45,"D",M28>=40,"E",M28<40,"F")} -> D | N29: {=_xlfn.IFS(N28>= 70,"A",N28>=60,"B",N28>=50,"C",N28>=45,"D",N28>=40,"E",N28<40,"F")} -> C | O29: {=_xlfn.IFS(O28>= 70,"A",O28>=60,"B",O28>=50,"C",O28>=45,"D",O28>=40,"E",O28<40,"F")} -> C | P29: {=_xlfn.IFS(P28>= 70,"A",P28>=60,"B",P28>=50,"C",P28>=45,"D",P28>=40,"E",P28<40,"F")} -> C | ... AF29: {=_xlfn.IFS(AF28>= 70,"A",AF28>=60,"B",AF28>=50,"C",AF28>=45,"D",AF28>=40,"E",AF28<40,"F")} -> B | AH29: {=_xlfn.IFS(AG29>= 70,"A",AG29>=60,"B",AG29>=50,"C",AG29>=45,"D",AG29>=40,"E",AG29<40,"F")} -> F | AJ29: {=_xlfn.IFS(AI29>= 70,"A",AI29>=60,"B",AI29>=50,"C",AI29>=45,"D",AI29>=40,"E",AI29<40,"F")} -> F | AL29: {=_xlfn.IFS(AK29>= 70,"A",AK29>=60,"B",AK29>=50,"C",AK29>=45,"D",AK29>=40,"E",AK29<40,"F")} -> F | AM29: =SUMIFS($I$4:$W$4,I28:W28,">0") -> 23 | AN29: =(SUMIFS($I$4:$W$4,I28:W28,">0")-SUMIFS($I$4:$W$4,I29:W29,"F")) -> 23 | AO29: =SUMIFS($I$4:$W$4,I29:W29,"F") -> 0
A30: 13 | I30: 45 | J30: 46 | K30: 47 | L30: 48 | M30: 49 | N30: 50 | O30: 51 | P30: 52 | Q30: 53 | R30: 54 | S30: 55 | T30: 56 | U30: 57 | V30: 58 | W30: 59 | X30: 60 | Y30: 61 | Z30: 62 | AA30: 63 | AB30: 64 | AC30: 65 | AD30: 66 | AE30: 67 | AF30: 68 | AH30: {=_xlfn.IFS(AG30>= 70,"A",AG30>=60,"B",AG30>=50,"C",AG30>=45,"D",AG30>=40,"E",AG30<40,"F")} -> F | AJ30: {=_xlfn.IFS(AI30>= 70,"A",AI30>=60,"B",AI30>=50,"C",AI30>=45,"D",AI30>=40,"E",AI30<40,"F")} -> F | AL30: {=_xlfn.IFS(AK30>= 70,"A",AK30>=60,"B",AK30>=50,"C",AK30>=45,"D",AK30>=40,"E",AK30<40,"F")} -> F | AP30: {=SUM(VLOOKUP(I31:W31,GRADEPOINT!$A$2:$B$7,2,0)*$I$4:$W$4)} -> 61 | AQ30: =ROUND(AP30/AM31,2) -> 2.65
I31: {=_xlfn.IFS(I30>= 70,"A",I30>=60,"B",I30>=50,"C",I30>=45,"D",I30>=40,"E",I30<40,"F")} -> D | J31: {=_xlfn.IFS(J30>= 70,"A",J30>=60,"B",J30>=50,"C",J30>=45,"D",J30>=40,"E",J30<40,"F")} -> D | K31: {=_xlfn.IFS(K30>= 70,"A",K30>=60,"B",K30>=50,"C",K30>=45,"D",K30>=40,"E",K30<40,"F")} -> D | L31: {=_xlfn.IFS(L30>= 70,"A",L30>=60,"B",L30>=50,"C",L30>=45,"D",L30>=40,"E",L30<40,"F")} -> D | M31: {=_xlfn.IFS(M30>= 70,"A",M30>=60,"B",M30>=50,"C",M30>=45,"D",M30>=40,"E",M30<40,"F")} -> D | N31: {=_xlfn.IFS(N30>= 70,"A",N30>=60,"B",N30>=50,"C",N30>=45,"D",N30>=40,"E",N30<40,"F")} -> C | O31: {=_xlfn.IFS(O30>= 70,"A",O30>=60,"B",O30>=50,"C",O30>=45,"D",O30>=40,"E",O30<40,"F")} -> C | P31: {=_xlfn.IFS(P30>= 70,"A",P30>=60,"B",P30>=50,"C",P30>=45,"D",P30>=40,"E",P30<40,"F")} -> C | ... AF31: {=_xlfn.IFS(AF30>= 70,"A",AF30>=60,"B",AF30>=50,"C",AF30>=45,"D",AF30>=40,"E",AF30<40,"F")} -> B | AH31: {=_xlfn.IFS(AG31>= 70,"A",AG31>=60,"B",AG31>=50,"C",AG31>=45,"D",AG31>=40,"E",AG31<40,"F")} -> F | AJ31: {=_xlfn.IFS(AI31>= 70,"A",AI31>=60,"B",AI31>=50,"C",AI31>=45,"D",AI31>=40,"E",AI31<40,"F")} -> F | AL31: {=_xlfn.IFS(AK31>= 70,"A",AK31>=60,"B",AK31>=50,"C",AK31>=45,"D",AK31>=40,"E",AK31<40,"F")} -> F | AM31: =SUMIFS($I$4:$W$4,I30:W30,">0") -> 23 | AN31: =(SUMIFS($I$4:$W$4,I30:W30,">0")-SUMIFS($I$4:$W$4,I31:W31,"F")) -> 23 | AO31: =SUMIFS($I$4:$W$4,I31:W31,"F") -> 0
A32: 14 | I32: 45 | J32: 46 | K32: 47 | L32: 48 | M32: 49 | N32: 50 | O32: 51 | P32: 52 | Q32: 53 | R32: 54 | S32: 55 | T32: 56 | U32: 57 | V32: 70 | W32: 59 | X32: 60 | Y32: 61 | Z32: 62 | AA32: 63 | AB32: 64 | AC32: 65 | AD32: 66 | AE32: 67 | AF32: 68 | AH32: {=_xlfn.IFS(AG32>= 70,"A",AG32>=60,"B",AG32>=50,"C",AG32>=45,"D",AG32>=40,"E",AG32<40,"F")} -> F | AJ32: {=_xlfn.IFS(AI32>= 70,"A",AI32>=60,"B",AI32>=50,"C",AI32>=45,"D",AI32>=40,"E",AI32<40,"F")} -> F | AL32: {=_xlfn.IFS(AK32>= 70,"A",AK32>=60,"B",AK32>=50,"C",AK32>=45,"D",AK32>=40,"E",AK32<40,"F")} -> F | AP32: {=SUM(VLOOKUP(I33:W33,GRADEPOINT!$A$2:$B$7,2,0)*$I$4:$W$4)} -> 63 | AQ32: =ROUND(AP32/AM33,2) -> 2.74
I33: {=_xlfn.IFS(I32>= 70,"A",I32>=60,"B",I32>=50,"C",I32>=45,"D",I32>=40,"E",I32<40,"F")} -> D | J33: {=_xlfn.IFS(J32>= 70,"A",J32>=60,"B",J32>=50,"C",J32>=45,"D",J32>=40,"E",J32<40,"F")} -> D | K33: {=_xlfn.IFS(K32>= 70,"A",K32>=60,"B",K32>=50,"C",K32>=45,"D",K32>=40,"E",K32<40,"F")} -> D | L33: {=_xlfn.IFS(L32>= 70,"A",L32>=60,"B",L32>=50,"C",L32>=45,"D",L32>=40,"E",L32<40,"F")} -> D | M33: {=_xlfn.IFS(M32>= 70,"A",M32>=60,"B",M32>=50,"C",M32>=45,"D",M32>=40,"E",M32<40,"F")} -> D | N33: {=_xlfn.IFS(N32>= 70,"A",N32>=60,"B",N32>=50,"C",N32>=45,"D",N32>=40,"E",N32<40,"F")} -> C | O33: {=_xlfn.IFS(O32>= 70,"A",O32>=60,"B",O32>=50,"C",O32>=45,"D",O32>=40,"E",O32<40,"F")} -> C | P33: {=_xlfn.IFS(P32>= 70,"A",P32>=60,"B",P32>=50,"C",P32>=45,"D",P32>=40,"E",P32<40,"F")} -> C | ... AF33: {=_xlfn.IFS(AF32>= 70,"A",AF32>=60,"B",AF32>=50,"C",AF32>=45,"D",AF32>=40,"E",AF32<40,"F")} -> B | AH33: {=_xlfn.IFS(AG33>= 70,"A",AG33>=60,"B",AG33>=50,"C",AG33>=45,"D",AG33>=40,"E",AG33<40,"F")} -> F | AJ33: {=_xlfn.IFS(AI33>= 70,"A",AI33>=60,"B",AI33>=50,"C",AI33>=45,"D",AI33>=40,"E",AI33<40,"F")} -> F | AL33: {=_xlfn.IFS(AK33>= 70,"A",AK33>=60,"B",AK33>=50,"C",AK33>=45,"D",AK33>=40,"E",AK33<40,"F")} -> F | AM33: =SUMIFS($I$4:$W$4,I32:W32,">0") -> 23 | AN33: =(SUMIFS($I$4:$W$4,I32:W32,">0")-SUMIFS($I$4:$W$4,I33:W33,"F")) -> 23 | AO33: =SUMIFS($I$4:$W$4,I33:W33,"F") -> 0
A34: 15 | I34: 45 | J34: 46 | K34: 47 | L34: 48 | M34: 49 | N34: 50 | O34: 51 | P34: 52 | Q34: 53 | R34: 54 | S34: 55 | T34: 56 | U34: 57 | V34: 58 | W34: 59 | X34: 60 | Y34: 61 | Z34: 62 | AA34: 63 | AB34: 64 | AC34: 65 | AD34: 66 | AE34: 67 | AF34: 68 | AH34: {=_xlfn.IFS(AG34>= 70,"A",AG34>=60,"B",AG34>=50,"C",AG34>=45,"D",AG34>=40,"E",AG34<40,"F")} -> F | AJ34: {=_xlfn.IFS(AI34>= 70,"A",AI34>=60,"B",AI34>=50,"C",AI34>=45,"D",AI34>=40,"E",AI34<40,"F")} -> F | AL34: {=_xlfn.IFS(AK34>= 70,"A",AK34>=60,"B",AK34>=50,"C",AK34>=45,"D",AK34>=40,"E",AK34<40,"F")} -> F | AP34: {=SUM(VLOOKUP(I35:W35,GRADEPOINT!$A$2:$B$7,2,0)*$I$4:$W$4)} -> 61 | AQ34: =ROUND(AP34/AM35,2) -> 2.65
I35: {=_xlfn.IFS(I34>= 70,"A",I34>=60,"B",I34>=50,"C",I34>=45,"D",I34>=40,"E",I34<40,"F")} -> D | J35: {=_xlfn.IFS(J34>= 70,"A",J34>=60,"B",J34>=50,"C",J34>=45,"D",J34>=40,"E",J34<40,"F")} -> D | K35: {=_xlfn.IFS(K34>= 70,"A",K34>=60,"B",K34>=50,"C",K34>=45,"D",K34>=40,"E",K34<40,"F")} -> D | L35: {=_xlfn.IFS(L34>= 70,"A",L34>=60,"B",L34>=50,"C",L34>=45,"D",L34>=40,"E",L34<40,"F")} -> D | M35: {=_xlfn.IFS(M34>= 70,"A",M34>=60,"B",M34>=50,"C",M34>=45,"D",M34>=40,"E",M34<40,"F")} -> D | N35: {=_xlfn.IFS(N34>= 70,"A",N34>=60,"B",N34>=50,"C",N34>=45,"D",N34>=40,"E",N34<40,"F")} -> C | O35: {=_xlfn.IFS(O34>= 70,"A",O34>=60,"B",O34>=50,"C",O34>=45,"D",O34>=40,"E",O34<40,"F")} -> C | P35: {=_xlfn.IFS(P34>= 70,"A",P34>=60,"B",P34>=50,"C",P34>=45,"D",P34>=40,"E",P34<40,"F")} -> C | ... AF35: {=_xlfn.IFS(AF34>= 70,"A",AF34>=60,"B",AF34>=50,"C",AF34>=45,"D",AF34>=40,"E",AF34<40,"F")} -> B | AH35: {=_xlfn.IFS(AG35>= 70,"A",AG35>=60,"B",AG35>=50,"C",AG35>=45,"D",AG35>=40,"E",AG35<40,"F")} -> F | AJ35: {=_xlfn.IFS(AI35>= 70,"A",AI35>=60,"B",AI35>=50,"C",AI35>=45,"D",AI35>=40,"E",AI35<40,"F")} -> F | AL35: {=_xlfn.IFS(AK35>= 70,"A",AK35>=60,"B",AK35>=50,"C",AK35>=45,"D",AK35>=40,"E",AK35<40,"F")} -> F | AM35: =SUMIFS($I$4:$W$4,I34:W34,">0") -> 23 | AN35: =(SUMIFS($I$4:$W$4,I34:W34,">0")-SUMIFS($I$4:$W$4,I35:W35,"F")) -> 23 | AO35: =SUMIFS($I$4:$W$4,I35:W35,"F") -> 0
A36: 16 | I36: 45 | J36: 46 | K36: 47 | L36: 48 | M36: 49 | N36: 50 | O36: 51 | P36: 52 | Q36: 53 | R36: 54 | S36: 55 | T36: 56 | U36: 57 | V36: 58 | W36: 59 | X36: 60 | Y36: 61 | Z36: 62 | AA36: 63 | AB36: 64 | AC36: 65 | AD36: 66 | AE36: 67 | AF36: 68 | AH36: {=_xlfn.IFS(AG36>= 70,"A",AG36>=60,"B",AG36>=50,"C",AG36>=45,"D",AG36>=40,"E",AG36<40,"F")} -> F | AJ36: {=_xlfn.IFS(AI36>= 70,"A",AI36>=60,"B",AI36>=50,"C",AI36>=45,"D",AI36>=40,"E",AI36<40,"F")} -> F | AL36: {=_xlfn.IFS(AK36>= 70,"A",AK36>=60,"B",AK36>=50,"C",AK36>=45,"D",AK36>=40,"E",AK36<40,"F")} -> F | AP36: {=SUM(VLOOKUP(I37:W37,GRADEPOINT!$A$2:$B$7,2,0)*$I$4:$W$4)} -> 61 | AQ36: =ROUND(AP36/AM37,2) -> 2.65
I37: {=_xlfn.IFS(I36>= 70,"A",I36>=60,"B",I36>=50,"C",I36>=45,"D",I36>=40,"E",I36<40,"F")} -> D | J37: {=_xlfn.IFS(J36>= 70,"A",J36>=60,"B",J36>=50,"C",J36>=45,"D",J36>=40,"E",J36<40,"F")} -> D | K37: {=_xlfn.IFS(K36>= 70,"A",K36>=60,"B",K36>=50,"C",K36>=45,"D",K36>=40,"E",K36<40,"F")} -> D | L37: {=_xlfn.IFS(L36>= 70,"A",L36>=60,"B",L36>=50,"C",L36>=45,"D",L36>=40,"E",L36<40,"F")} -> D | M37: {=_xlfn.IFS(M36>= 70,"A",M36>=60,"B",M36>=50,"C",M36>=45,"D",M36>=40,"E",M36<40,"F")} -> D | N37: {=_xlfn.IFS(N36>= 70,"A",N36>=60,"B",N36>=50,"C",N36>=45,"D",N36>=40,"E",N36<40,"F")} -> C | O37: {=_xlfn.IFS(O36>= 70,"A",O36>=60,"B",O36>=50,"C",O36>=45,"D",O36>=40,"E",O36<40,"F")} -> C | P37: {=_xlfn.IFS(P36>= 70,"A",P36>=60,"B",P36>=50,"C",P36>=45,"D",P36>=40,"E",P36<40,"F")} -> C | ... AF37: {=_xlfn.IFS(AF36>= 70,"A",AF36>=60,"B",AF36>=50,"C",AF36>=45,"D",AF36>=40,"E",AF36<40,"F")} -> B | AH37: {=_xlfn.IFS(AG37>= 70,"A",AG37>=60,"B",AG37>=50,"C",AG37>=45,"D",AG37>=40,"E",AG37<40,"F")} -> F | AJ37: {=_xlfn.IFS(AI37>= 70,"A",AI37>=60,"B",AI37>=50,"C",AI37>=45,"D",AI37>=40,"E",AI37<40,"F")} -> F | AL37: {=_xlfn.IFS(AK37>= 70,"A",AK37>=60,"B",AK37>=50,"C",AK37>=45,"D",AK37>=40,"E",AK37<40,"F")} -> F | AM37: =SUMIFS($I$4:$W$4,I36:W36,">0") -> 23 | AN37: =(SUMIFS($I$4:$W$4,I36:W36,">0")-SUMIFS($I$4:$W$4,I37:W37,"F")) -> 23 | AO37: =SUMIFS($I$4:$W$4,I37:W37,"F") -> 0
A38: 17 | I38: 45 | J38: 46 | K38: 47 | L38: 48 | M38: 49 | N38: 50 | O38: 51 | P38: 52 | Q38: 53 | R38: 54 | S38: 55 | T38: 56 | U38: 57 | V38: 58 | W38: 59 | X38: 60 | Y38: 61 | Z38: 62 | AA38: 63 | AB38: 64 | AC38: 65 | AD38: 66 | AE38: 67 | AF38: 68 | AH38: {=_xlfn.IFS(AG38>= 70,"A",AG38>=60,"B",AG38>=50,"C",AG38>=45,"D",AG38>=40,"E",AG38<40,"F")} -> F | AJ38: {=_xlfn.IFS(AI38>= 70,"A",AI38>=60,"B",AI38>=50,"C",AI38>=45,"D",AI38>=40,"E",AI38<40,"F")} -> F | AL38: {=_xlfn.IFS(AK38>= 70,"A",AK38>=60,"B",AK38>=50,"C",AK38>=45,"D",AK38>=40,"E",AK38<40,"F")} -> F | AP38: {=SUM(VLOOKUP(I39:W39,GRADEPOINT!$A$2:$B$7,2,0)*$I$4:$W$4)} -> 61 | AQ38: =ROUND(AP38/AM39,2) -> 2.65
I39: {=_xlfn.IFS(I38>= 70,"A",I38>=60,"B",I38>=50,"C",I38>=45,"D",I38>=40,"E",I38<40,"F")} -> D | J39: {=_xlfn.IFS(J38>= 70,"A",J38>=60,"B",J38>=50,"C",J38>=45,"D",J38>=40,"E",J38<40,"F")} -> D | K39: {=_xlfn.IFS(K38>= 70,"A",K38>=60,"B",K38>=50,"C",K38>=45,"D",K38>=40,"E",K38<40,"F")} -> D | L39: {=_xlfn.IFS(L38>= 70,"A",L38>=60,"B",L38>=50,"C",L38>=45,"D",L38>=40,"E",L38<40,"F")} -> D | M39: {=_xlfn.IFS(M38>= 70,"A",M38>=60,"B",M38>=50,"C",M38>=45,"D",M38>=40,"E",M38<40,"F")} -> D | N39: {=_xlfn.IFS(N38>= 70,"A",N38>=60,"B",N38>=50,"C",N38>=45,"D",N38>=40,"E",N38<40,"F")} -> C | O39: {=_xlfn.IFS(O38>= 70,"A",O38>=60,"B",O38>=50,"C",O38>=45,"D",O38>=40,"E",O38<40,"F")} -> C | P39: {=_xlfn.IFS(P38>= 70,"A",P38>=60,"B",P38>=50,"C",P38>=45,"D",P38>=40,"E",P38<40,"F")} -> C | ... AF39: {=_xlfn.IFS(AF38>= 70,"A",AF38>=60,"B",AF38>=50,"C",AF38>=45,"D",AF38>=40,"E",AF38<40,"F")} -> B | AH39: {=_xlfn.IFS(AG39>= 70,"A",AG39>=60,"B",AG39>=50,"C",AG39>=45,"D",AG39>=40,"E",AG39<40,"F")} -> F | AJ39: {=_xlfn.IFS(AI39>= 70,"A",AI39>=60,"B",AI39>=50,"C",AI39>=45,"D",AI39>=40,"E",AI39<40,"F")} -> F | AL39: {=_xlfn.IFS(AK39>= 70,"A",AK39>=60,"B",AK39>=50,"C",AK39>=45,"D",AK39>=40,"E",AK39<40,"F")} -> F | AM39: =SUMIFS($I$4:$W$4,I38:W38,">0") -> 23 | AN39: =(SUMIFS($I$4:$W$4,I38:W38,">0")-SUMIFS($I$4:$W$4,I39:W39,"F")) -> 23 | AO39: =SUMIFS($I$4:$W$4,I39:W39,"F") -> 0
A40: 18 | I40: 45 | J40: 46 | K40: 47 | L40: 48 | M40: 49 | N40: 50 | O40: 51 | P40: 52 | Q40: 53 | R40: 54 | S40: 55 | T40: 56 | U40: 57 | V40: 58 | W40: 59 | X40: 60 | Y40: 61 | Z40: 62 | AA40: 63 | AB40: 64 | AC40: 65 | AD40: 66 | AE40: 67 | AF40: 68 | AH40: {=_xlfn.IFS(AG40>= 70,"A",AG40>=60,"B",AG40>=50,"C",AG40>=45,"D",AG40>=40,"E",AG40<40,"F")} -> F | AJ40: {=_xlfn.IFS(AI40>= 70,"A",AI40>=60,"B",AI40>=50,"C",AI40>=45,"D",AI40>=40,"E",AI40<40,"F")} -> F | AL40: {=_xlfn.IFS(AK40>= 70,"A",AK40>=60,"B",AK40>=50,"C",AK40>=45,"D",AK40>=40,"E",AK40<40,"F")} -> F | AP40: {=SUM(VLOOKUP(I41:W41,GRADEPOINT!$A$2:$B$7,2,0)*$I$4:$W$4)} -> 61 | AQ40: =ROUND(AP40/AM41,2) -> 2.65
...

Sheet Sheet4
A1: 2 | B1: 2 | C1: 1 | D1: 2 | E1: 1 | F1: 3 | G1: 2 | H1: 2 | I1: 2 | J1: 1 | K1: 1 | L1: 1 | M1: 1 | N1: 1 | O1: 1
A2: D | B2: D | C2: D | D2: D | E2: D | F2: C | G2: F | H2: C | I2: F | J2: C | K2: C | L2: C | M2: C | N2: C | O2: F
A3: =VLOOKUP(A2,GRADEPOINT!$A$2:$B$7,2,0) -> 2 | B3: =VLOOKUP(B2,GRADEPOINT!$A$2:$B$7,2,0) -> 2 | C3: =VLOOKUP(C2,GRADEPOINT!$A$2:$B$7,2,0) -> 2 | D3: =VLOOKUP(D2,GRADEPOINT!$A$2:$B$7,2,0) -> 2 | E3: =VLOOKUP(E2,GRADEPOINT!$A$2:$B$7,2,0) -> 2 | F3: =VLOOKUP(F2,GRADEPOINT!$A$2:$B$7,2,0) -> 3 | G3: =VLOOKUP(G2,GRADEPOINT!$A$2:$B$7,2,0) -> 0 | H3: =VLOOKUP(H2,GRADEPOINT!$A$2:$B$7,2,0) -> 3 | ... O3: =VLOOKUP(O2,GRADEPOINT!$A$2:$B$7,2,0) -> 0 | Q3: =SUM(A3:O3) -> 31
A4: =A3*A1 -> 4 | B4: =B3*B1 -> 4 | C4: =C3*C1 -> 2 | D4: =D3*D1 -> 4 | E4: =E3*E1 -> 2 | F4: =F3*F1 -> 9 | G4: =G3*G1 -> 0 | H4: =H3*H1 -> 6 | ... O4: =O3*O1 -> 0 | Q4: =SUM(A4:O4) -> 46
A5: 45 | B5: 46 | C5: 47 | D5: 48 | E5: 49 | F5: 50 | G5: 51 | H5: 52 | I5: 53 | J5: 54 | K5: 55 | L5: 56 | M5: 57 | N5: 58 | O5: 59
A6: {=_xlfn.IFS(A5>= 70,"A",A5>=60,"B",A5>=50,"C",A5>=45,"D",A5>=40,"E",A5<40,"F")} -> D | B6: {=_xlfn.IFS(B5>= 70,"A",B5>=60,"B",B5>=50,"C",B5>=45,"D",B5>=40,"E",B5<40,"F")} -> D | C6: {=_xlfn.IFS(C5>= 70,"A",C5>=60,"B",C5>=50,"C",C5>=45,"D",C5>=40,"E",C5<40,"F")} -> D | D6: {=_xlfn.IFS(D5>= 70,"A",D5>=60,"B",D5>=50,"C",D5>=45,"D",D5>=40,"E",D5<40,"F")} -> D | E6: {=_xlfn.IFS(E5>= 70,"A",E5>=60,"B",E5>=50,"C",E5>=45,"D",E5>=40,"E",E5<40,"F")} -> D | F6: {=_xlfn.IFS(F5>= 70,"A",F5>=60,"B",F5>=50,"C",F5>=45,"D",F5>=40,"E",F5<40,"F")} -> C | G6: {=_xlfn.IFS(G5>= 70,"A",G5>=60,"B",G5>=50,"C",G5>=45,"D",G5>=40,"E",G5<40,"F")} -> C | H6: {=_xlfn.IFS(H5>= 70,"A",H5>=60,"B",H5>=50,"C",H5>=45,"D",H5>=40,"E",H5<40,"F")} -> C | ... O6: {=_xlfn.IFS(O5>= 70,"A",O5>=60,"B",O5>=50,"C",O5>=45,"D",O5>=40,"E",O5<40,"F")} -> C
A7: =VLOOKUP(A6,GRADEPOINT!$A$2:$B$7,2,0) -> 2 | B7: =VLOOKUP(B6,GRADEPOINT!$A$2:$B$7,2,0) -> 2 | C7: =VLOOKUP(C6,GRADEPOINT!$A$2:$B$7,2,0) -> 2 | D7: =VLOOKUP(D6,GRADEPOINT!$A$2:$B$7,2,0) -> 2 | E7: =VLOOKUP(E6,GRADEPOINT!$A$2:$B$7,2,0) -> 2 | F7: =VLOOKUP(F6,GRADEPOINT!$A$2:$B$7,2,0) -> 3 | G7: =VLOOKUP(G6,GRADEPOINT!$A$2:$B$7,2,0) -> 3 | H7: =VLOOKUP(H6,GRADEPOINT!$A$2:$B$7,2,0) -> 3 | ... O7: =VLOOKUP(O6,GRADEPOINT!$A$2:$B$7,2,0) -> 3 | Q7: =SUM(A7:O7) -> 40
A8: =A7*A1 -> 4 | B8: =B7*B1 -> 4 | C8: =C7*C1 -> 2 | D8: =D7*D1 -> 4 | E8: =E7*E1 -> 2 | F8: =F7*F1 -> 9 | G8: =G7*G1 -> 6 | H8: =H7*H1 -> 6 | ... O8: =O7*O1 -> 3 | Q8: =SUM(A8:O8) -> 61

Sheet Sheet3
A1: {=TRANSPOSE('REG. COURSES'!#REF!)} -> #REF!

Sheet GRADEPOINT
A1: GRADE POINTS
A2: A | B2: 5
A3: B | B3: 4
A4: C | B4: 3
A5: D | B5: 2
A6: E | B6: 1
A7: F | B7: 0

Sheet REG. COURSES
A2: COLLEGE OF SCIENCE AND COMPUTING
A4: DEPARTMENT OF MATHEMATICS AND COMPUTING
A5: SESSION | B5: 2024/2025 | I5: SESSION | J5: 2024/2025
A6: LEVEL | B6: 100 | I6: LEVEL | J6: 200
B7: YEAR ONE | J7: YEAR TWO
A8: Course Abbreviation | B8: Course Code | C8: Credit Unit | D8: Course Title | I8: Course Abbreviation | J8: Course Code | K8: Credit Unit | L8: Course Title
A9: FIRST SEMESTER | I9: FIRST SEMESTER
A10: GST | B10: 111 | C10: 2 | I10: GST | J10: 111 | K10: 2
A11: PHY | B11: 101 | C11: 2 | I11: PHY | J11: 101 | K11: 2
A12: WU | B12: 111 | C12: 1 | I12: WU | J12: 111 | K12: 1
A13: WU-GST | B13: 101 | C13: 2 | I13: WU-GST | J13: 101 | K13: 2
A14: WU-GST | B14: 111 | C14: 1 | I14: WU-GST | J14: 111 | K14: 1
A15: COS | B15: 101 | C15: 3 | I15: COS | J15: 101 | K15: 3
A16: BUA | B16: 101 | C16: 2 | I16: BUA | J16: 101 | K16: 2
A17: MTH | B17: 101 | C17: 2 | I17: MTH | J17: 101 | K17: 2
A18: MTH | B18: 103 | C18: 2 | I18: MTH | J18: 103 | K18: 2
A19: MTH | B19: 104 | C19: 1 | I19: MTH | J19: 104
A20: MTH | B20: 105 | C20: 1 | I20: MTH | J20: 105
A21: MTH | B21: 106 | C21: 1 | I21: MTH | J21: 106
A22: MTH | B22: 107 | C22: 1 | I22: MTH | J22: 107
A23: MTH | B23: 108 | C23: 1 | I23: MTH | J23: 108
A24: MTH | B24: 109 | C24: 1 | I24: MTH | J24: 109
A27: SECOND SEMESTER | I27: SECOND SEMESTER
A28: GST | B28: 112 | C28: 2 | I28: GST | J28: 112 | K28: 2
A29: PHY | B29: 102 | C29: 2 | I29: PHY | J29: 102 | K29: 2
A30: WU-GST | B30: 112 | C30: 1 | I30: WU-GST | J30: 112 | K30: 1
A31: WU | B31: 100 | C31: 1 | I31: WU | J31: 100 | K31: 1
A32: STA | B32: 112 | C32: 3 | I32: STA | J32: 112 | K32: 3
A33: WU-MTH | B33: 106 | C33: 1 | I33: WU-MTH | J33: 106 | K33: 1
A34: MTH | B34: 102 | C34: 2 | I34: MTH | J34: 102 | K34: 2
A35: MTH | I35: MTH
A36: MTH | I36: MTH
A37: MTH | I37: MTH
A38: MTH | I38: MTH
A39: MTH | I39: MTH
A40: MTH | I40: MTH
A41: MTH | I41: MTH
